Workbook

Sheet Index
B2: MATERIAL PRICE LIST & RATE DATABASE
B3: Saeed Al Siraj Glass & Aluminium Works L.L.C. | Estimation Department | Aluminium, Glass, MS & SS Works
B5: Rate validity / last reviewed: | D5: =Settings!C21 -> 09-Oct-2026 | F5: =HYPERLINK("#Search!C5",">> SEARCH MATERIAL <<") -> >> SEARCH MATERIAL <<
B6: VAT: | D6: =VAT -> 0.05
B7: Default O&P: | D7: =OHP -> 0.2 | F7: =HYPERLINK("#Settings!C6","Edit base rates / VAT / O&P") -> Edit base rates / VAT / O&P
B8: Total items: | D8: =COUNTA('ALL ITEMS'!D3:D764)-COUNTBLANK('ALL ITEMS'!D3:D764) -> 537 | F8: =HYPERLINK("#'ALL ITEMS'!A1","View master list (all items)") -> View master list (all items)
B10: No. | C10: Category | D10: Code | E10: Scope / Contents | F10: Items | G10: Open | H10: Sheet | K10: All Categories
B11: 1 | C11: Aluminium Profiles & Systems | D11: AL | E11: Extrusions by kg, standard sections, window/door/curtain wall/pergola profiles | F11: =COUNTA('01 Aluminium'!C5:C72) -> 53 | G11: =HYPERLINK("#'01 Aluminium'!A1","Open >") -> Open > | H11: 01 Aluminium | K11: Aluminium Profiles & Systems
B12: 2 | C12: Glass - Float, Tempered, Laminated & DGU | D12: GL | E12: Clear, tinted, reflective, tempered, laminated, insulated, low-E, low-iron, fire-rated | F12: =COUNTA('02 Glass'!C5:C73) -> 54 | G12: =HYPERLINK("#'02 Glass'!A1","Open >") -> Open > | H12: 02 Glass | K12: Glass - Float, Tempered, Laminated & DGU
B13: 3 | C13: Glass Processing & Fabrication Charges | D13: GP | E13: Edge work, holes, cut-outs, bevelling, sand-blasting, film, cutting & handling | F13: =COUNTA('03 Glass Processing'!C5:C42) -> 23 | G13: =HYPERLINK("#'03 Glass Processing'!A1","Open >") -> Open > | H13: 03 Glass Processing | K13: Glass Processing & Fabrication Charges
B14: 4 | C14: Mirrors | D14: MR | E14: Silver, coloured, safety-backed, bevelled, LED & framed mirrors | F14: =COUNTA('04 Mirrors'!C5:C36) -> 17 | G14: =HYPERLINK("#'04 Mirrors'!A1","Open >") -> Open > | H14: 04 Mirrors | K14: Mirrors
B15: 5 | C15: Hardware - Doors & Windows | D15: HW | E15: Floor springs, closers, locks, handles, hinges, rollers, friction stays, multipoint locks | F15: =COUNTA('05 Door & Window HW'!C5:C57) -> 38 | G15: =HYPERLINK("#'05 Door & Window HW'!A1","Open >") -> Open > | H15: 05 Door & Window HW | K15: Hardware - Doors & Windows
B16: 6 | C16: Glass Fittings - Partition, Shower & Spider | D16: GF | E16: Patch fittings, shower hinges, clamps, spider / routel, sliding glass systems | F16: =COUNTA('06 Glass Fittings HW'!C5:C49) -> 30 | G16: =HYPERLINK("#'06 Glass Fittings HW'!A1","Open >") -> Open > | H16: 06 Glass Fittings HW | K16: Glass Fittings - Partition, Shower & Spider
B17: 7 | C17: Balustrade & Handrail Components | D17: BH | E17: SS posts, glass clamps, spigots, standoffs, handrail brackets & end caps | F17: =COUNTA('07 Balustrade HW'!C5:C42) -> 23 | G17: =HYPERLINK("#'07 Balustrade HW'!A1","Open >") -> Open > | H17: 07 Balustrade HW | K17: Balustrade & Handrail Components
B18: 8 | C18: Sealants, Gaskets, Fixings & Consumables | D18: SF | E18: Silicones, foams, EPDM, tapes, anchors, screws, brackets, shims, tools & consumables | F18: =COUNTA('08 Sealants & Fixings'!C5:C65) -> 46 | G18: =HYPERLINK("#'08 Sealants & Fixings'!A1","Open >") -> Open > | H18: 08 Sealants & Fixings | K18: Sealants, Gaskets, Fixings & Consumables
B19: 9 | C19: Cladding, ACP & Facade Panels | D19: CL | E19: ACP, solid aluminium, perforated, louvered and HPL panels | F19: =COUNTA('09 Cladding & ACP'!C5:C36) -> 17 | G19: =HYPERLINK("#'09 Cladding & ACP'!A1","Open >") -> Open > | H19: 09 Cladding & ACP | K19: Cladding, ACP & Facade Panels
B20: 10 | C20: Mild Steel (MS) - Sections, Plates & Sheets | D20: MS | E20: SHS, RHS, angles, channels, beams, flats, rounds, pipes, plates, GI sheets, grating | F20: =COUNTA('10 Mild Steel'!C5:C82) -> 63 | G20: =HYPERLINK("#'10 Mild Steel'!A1","Open >") -> Open > | H20: 10 Mild Steel | K20: Mild Steel (MS) - Sections, Plates & Sheets
B21: 11 | C21: Stainless Steel (SS) - Tubes, Sheets & Drains | D21: SS | E21: SS 304 / 316 round, square & rectangular tubes, sheets, flats, rods, linear drains | F21: =COUNTA('11 Stainless Steel'!C5:C61) -> 42 | G21: =HYPERLINK("#'11 Stainless Steel'!A1","Open >") -> Open > | H21: 11 Stainless Steel | K21: Stainless Steel (SS) - Tubes, Sheets & Drains
B22: 12 | C22: Automatic Doors, Operators & Shutters | D22: AD | E22: Sliding / swing operators, sensors, access control, rolling shutters | F22: =COUNTA('12 Auto Doors & Shutters'!C5:C37) -> 18 | G22: =HYPERLINK("#'12 Auto Doors & Shutters'!A1","Open >") -> Open > | H22: 12 Auto Doors & Shutters | K22: Automatic Doors, Operators & Shutters
B23: 13 | C23: Coating, Finishing & Treatment Services | D23: CF | E23: Powder coating, anodizing, PVDF, galvanizing, painting, polishing (job-work rates) | F23: =COUNTA('13 Coating & Finishing'!C5:C36) -> 17 | G23: =HYPERLINK("#'13 Coating & Finishing'!A1","Open >") -> Open > | H23: 13 Coating & Finishing | K23: Coating, Finishing & Treatment Services
B24: 14 | C24: Labour, Equipment, Transport & Misc. Costs | D24: LB | E24: Manpower day rates, access equipment, cranes, transport, scaffolding, testing | F24: =COUNTA('14 Labour & Equipment'!C5:C59) -> 40 | G24: =HYPERLINK("#'14 Labour & Equipment'!A1","Open >") -> Open > | H24: 14 Labour & Equipment | K24: Labour, Equipment, Transport & Misc. Costs
B25: 15 | C25: Finished Systems - Budget Supply & Install Rates | D25: SI | E25: All-in budget rates for quick estimates (material + fabrication + installation) | F25: =COUNTA('15 System Rates S&I'!C5:C75) -> 56 | G25: =HYPERLINK("#'15 System Rates S&I'!A1","Open >") -> Open > | H25: 15 System Rates S&I | K25: Finished Systems - Budget Supply & Install Rates
C26: TOTAL | F26: =SUM(F11:F25) -> 537
B28: HOW TO USE
B29: 1. FIND: Go to 'Search' - type any keyword (size, brand, item) - results with rates appear instantly.
B30: 2. BROWSE: Click 'Open' above to go to a category sheet. Use the filter arrows on the header row.
B31: 3. UPDATE RATE: Type the new Basic Rate (blue) in the category sheet, set Rate Status, Supplier, Quote Ref & Date, then log it in 'Rate Log'.
B32: 4. ADD ITEM: Use the yellow spare rows at the bottom of each category sheet - the code, net, selling & VAT rates fill in automatically.
B33: 5. MARKET CHANGE: Change aluminium / steel / SS rate per kg, VAT or O&P in 'Settings' - all linked rates (green) update automatically.
B34: 6. NET COST RATE = Basic Rate x (1 + Wastage %). SELLING = Net Cost x (1 + O&P). SELLING incl. VAT = Selling x (1 + VAT).
B36: LEGEND
C37: Blue text | D37: Input / editable value
C38: Black text | D38: Formula - do not overwrite
C39: Green text | D39: Linked to Settings / another sheet
C40: Indicative | D40: Budget market rate - confirm before final quote
C41: Quoted | D41: Rate taken from a supplier quotation
C42: Verified | D42: Rate confirmed by recent purchase / LPO
C43: Obsolete | D43: Item no longer used (shown struck-through)
B45: UNITS
B46: m2 = square metre | lm = linear metre | kg = kilogram | nos = numbers | set / pair / pkt / box / roll | ltr = litre | day / hr / month / trip | ls = lump sum | % = percentage
...

Sheet Search
B2: QUICK MATERIAL SEARCH
B3: Type one or more words in any order (e.g. aluminium sheet, 12 tempered, floor spring, 316 tube, DGU low e) - every word must match the start of a word. Pick a category if needed. Results update instantly.
Q4: =TRIM(SUBSTITUTE(SUBSTITUTE(SUBSTITUTE(SUBSTITUTE(SUBSTITUTE(SUBSTITUTE(SUBSTITUTE(SUBSTITUTE(SUBSTITUTE(LOWER($C$5),"*","x"),"?"," "),"~"," "),"("," "),")"," "),"/"," "),"-"," "),","," "),";"," "))&" " -> aluminium sheet
A5: Search keyword: | C5: aluminium sheet | G5: Tip: clear the keyword to list a whole category. | P5: =IF(AND(LEN(R5)>3,RIGHT(R5,1)="s",RIGHT(R5,2)<>"ss"),LEFT(R5,LEN(R5)-1),R5) -> aluminium | Q5: =IFERROR(MID(Q4,FIND(" ",Q4)+1,999),"") -> sheet | R5: =IFERROR(LEFT(Q4,FIND(" ",Q4)-1),"") -> aluminium
A6: Category: | C6: All Categories | G6: Max 300 results shown - refine keyword if needed. | P6: =IF(AND(LEN(R6)>3,RIGHT(R6,1)="s",RIGHT(R6,2)<>"ss"),LEFT(R6,LEN(R6)-1),R6) -> sheet | Q6: =IFERROR(MID(Q5,FIND(" ",Q5)+1,999),"") | R6: =IFERROR(LEFT(Q5,FIND(" ",Q5)-1),"") -> sheet
A7: Items found: | C7: =COUNT('ALL ITEMS'!M3:M764) -> 8 | D7: =IF(C7=0,"No match - check spelling or try fewer words (e.g. 40x40 tube)","") | G7: =HYPERLINK("#Index!A1","<< Back to Index") -> << Back to Index | P7: =IF(AND(LEN(R7)>3,RIGHT(R7,1)="s",RIGHT(R7,2)<>"ss"),LEFT(R7,LEN(R7)-1),R7) | Q7: =IFERROR(MID(Q6,FIND(" ",Q6)+1,999),"") | R7: =IFERROR(LEFT(Q6,FIND(" ",Q6)-1),"")
A8: Words matched: | C8: =IF(P5="","(none - showing all)",P5&IF(P6="",""," + "&P6)&IF(P7="",""," + "&P7)&IF(P8="",""," + "&P8)&IF(P9="",""," + "&P9)&IF(P10="",""," + "&P10)) -> aluminium + sheet | P8: =IF(AND(LEN(R8)>3,RIGHT(R8,1)="s",RIGHT(R8,2)<>"ss"),LEFT(R8,LEN(R8)-1),R8) | Q8: =IFERROR(MID(Q7,FIND(" ",Q7)+1,999),"") | R8: =IFERROR(LEFT(Q7,FIND(" ",Q7)-1),"")
A9: # | B9: Item Code | C9: Category | D9: Item Description | E9: Specification / Size | F9: Finish / Colour | G9: Brand / Origin | H9: Unit | I9: Net Cost (AED) | J9: Selling (AED) | K9: Selling incl. VAT | L9: Rate Status | P9: =IF(AND(LEN(R9)>3,RIGHT(R9,1)="s",RIGHT(R9,2)<>"ss"),LEFT(R9,LEN(R9)-1),R9) | Q9: =IFERROR(MID(Q8,FIND(" ",Q8)+1,999),"") | R9: =IFERROR(LEFT(Q8,FIND(" ",Q8)-1),"")
A10: =IF($N10="","",ROWS($N$10:N10)) -> 1 | B10: =IF($N10="","",INDEX('ALL ITEMS'!$B:$B,$N10)) -> AL-051 | C10: =IF($N10="","",INDEX('ALL ITEMS'!$A:$A,$N10)) -> Aluminium Profiles & Systems | D10: =IF($N10="","",INDEX('ALL ITEMS'!$D:$D,$N10)) -> Aluminium flat sheet | E10: =IF($N10="","",INDEX('ALL ITEMS'!$E:$E,$N10)) -> 2.0 mm, 1250 x 2500 | F10: =IF($N10="","",INDEX('ALL ITEMS'!$F:$F,$N10)) -> Mill finish | G10: =IF($N10="","",INDEX('ALL ITEMS'!$G:$G,$N10)) -> Local / Imported | H10: =IF($N10="","",INDEX('ALL ITEMS'!$H:$H,$N10)) -> m2 | I10: =IF($N10="","",INDEX('ALL ITEMS'!$I:$I,$N10)) -> 50.4 | J10: =IF($N10="","",INDEX('ALL ITEMS'!$J:$J,$N10)) -> 60.48 | K10: =IF($N10="","",INDEX('ALL ITEMS'!$K:$K,$N10)) -> 63.5 | L10: =IF($N10="","",INDEX('ALL ITEMS'!$L:$L,$N10)) -> Indicative | N10: =IF(ROWS($N$10:N10)>$C$7,"",SMALL('ALL ITEMS'!$M$3:$M$764,ROWS($N$10:N10))) -> 53 | P10: =IF(AND(LEN(R10)>3,RIGHT(R10,1)="s",RIGHT(R10,2)<>"ss"),LEFT(R10,LEN(R10)-1),R10) | Q10: =IFERROR(MID(Q9,FIND(" ",Q9)+1,999),"") | R10: =IFERROR(LEFT(Q9,FIND(" ",Q9)-1),"")
A11: =IF($N11="","",ROWS($N$10:N11)) -> 2 | B11: =IF($N11="","",INDEX('ALL ITEMS'!$B:$B,$N11)) -> AL-052 | C11: =IF($N11="","",INDEX('ALL ITEMS'!$A:$A,$N11)) -> Aluminium Profiles & Systems | D11: =IF($N11="","",INDEX('ALL ITEMS'!$D:$D,$N11)) -> Aluminium flat sheet | E11: =IF($N11="","",INDEX('ALL ITEMS'!$E:$E,$N11)) -> 3.0 mm, 1250 x 2500 | F11: =IF($N11="","",INDEX('ALL ITEMS'!$F:$F,$N11)) -> Mill finish | G11: =IF($N11="","",INDEX('ALL ITEMS'!$G:$G,$N11)) -> Local / Imported | H11: =IF($N11="","",INDEX('ALL ITEMS'!$H:$H,$N11)) -> m2 | I11: =IF($N11="","",INDEX('ALL ITEMS'!$I:$I,$N11)) -> 73.5 | J11: =IF($N11="","",INDEX('ALL ITEMS'!$J:$J,$N11)) -> 88.2 | K11: =IF($N11="","",INDEX('ALL ITEMS'!$K:$K,$N11)) -> 92.61 | L11: =IF($N11="","",INDEX('ALL ITEMS'!$L:$L,$N11)) -> Indicative | N11: =IF(ROWS($N$10:N11)>$C$7,"",SMALL('ALL ITEMS'!$M$3:$M$764,ROWS($N$10:N11))) -> 54
A12: =IF($N12="","",ROWS($N$10:N12)) -> 3 | B12: =IF($N12="","",INDEX('ALL ITEMS'!$B:$B,$N12)) -> AL-053 | C12: =IF($N12="","",INDEX('ALL ITEMS'!$A:$A,$N12)) -> Aluminium Profiles & Systems | D12: =IF($N12="","",INDEX('ALL ITEMS'!$D:$D,$N12)) -> Aluminium chequered plate | E12: =IF($N12="","",INDEX('ALL ITEMS'!$E:$E,$N12)) -> 3.0 mm tread | F12: =IF($N12="","",INDEX('ALL ITEMS'!$F:$F,$N12)) -> Mill finish | G12: =IF($N12="","",INDEX('ALL ITEMS'!$G:$G,$N12)) -> Local / Imported | H12: =IF($N12="","",INDEX('ALL ITEMS'!$H:$H,$N12)) -> m2 | I12: =IF($N12="","",INDEX('ALL ITEMS'!$I:$I,$N12)) -> 89.25 | J12: =IF($N12="","",INDEX('ALL ITEMS'!$J:$J,$N12)) -> 107.1 | K12: =IF($N12="","",INDEX('ALL ITEMS'!$K:$K,$N12)) -> 112.46 | L12: =IF($N12="","",INDEX('ALL ITEMS'!$L:$L,$N12)) -> Indicative | N12: =IF(ROWS($N$10:N12)>$C$7,"",SMALL('ALL ITEMS'!$M$3:$M$764,ROWS($N$10:N12))) -> 55
A13: =IF($N13="","",ROWS($N$10:N13)) -> 4 | B13: =IF($N13="","",INDEX('ALL ITEMS'!$B:$B,$N13)) -> CL-001 | C13: =IF($N13="","",INDEX('ALL ITEMS'!$A:$A,$N13)) -> Cladding, ACP & Facade Panels | D13: =IF($N13="","",INDEX('ALL ITEMS'!$D:$D,$N13)) -> Aluminium composite panel (ACP) | E13: =IF($N13="","",INDEX('ALL ITEMS'!$E:$E,$N13)) -> 4 mm, 0.3 mm skin, non-FR | F13: =IF($N13="","",INDEX('ALL ITEMS'!$F:$F,$N13)) -> PVDF | G13: =IF($N13="","",INDEX('ALL ITEMS'!$G:$G,$N13)) -> Alubond / Alucobond / Equiv. | H13: =IF($N13="","",INDEX('ALL ITEMS'!$H:$H,$N13)) -> m2 | I13: =IF($N13="","",INDEX('ALL ITEMS'!$I:$I,$N13)) -> 60.5 | J13: =IF($N13="","",INDEX('ALL ITEMS'!$J:$J,$N13)) -> 72.6 | K13: =IF($N13="","",INDEX('ALL ITEMS'!$K:$K,$N13)) -> 76.23 | L13: =IF($N13="","",INDEX('ALL ITEMS'!$L:$L,$N13)) -> Indicative | N13: =IF(ROWS($N$10:N13)>$C$7,"",SMALL('ALL ITEMS'!$M$3:$M$764,ROWS($N$10:N13))) -> 407
A14: =IF($N14="","",ROWS($N$10:N14)) -> 5 | B14: =IF($N14="","",INDEX('ALL ITEMS'!$B:$B,$N14)) -> CL-002 | C14: =IF($N14="","",INDEX('ALL ITEMS'!$A:$A,$N14)) -> Cladding, ACP & Facade Panels | D14: =IF($N14="","",INDEX('ALL ITEMS'!$D:$D,$N14)) -> Aluminium composite panel - fire rated FR (B1) | E14: =IF($N14="","",INDEX('ALL ITEMS'!$E:$E,$N14)) -> 4 mm, 0.5 mm skin | F14: =IF($N14="","",INDEX('ALL ITEMS'!$F:$F,$N14)) -> PVDF | G14: =IF($N14="","",INDEX('ALL ITEMS'!$G:$G,$N14)) -> Alubond / Alucobond / Equiv. | H14: =IF($N14="","",INDEX('ALL ITEMS'!$H:$H,$N14)) -> m2 | I14: =IF($N14="","",INDEX('ALL ITEMS'!$I:$I,$N14)) -> 82.5 | J14: =IF($N14="","",INDEX('ALL ITEMS'!$J:$J,$N14)) -> 99 | K14: =IF($N14="","",INDEX('ALL ITEMS'!$K:$K,$N14)) -> 103.95 | L14: =IF($N14="","",INDEX('ALL ITEMS'!$L:$L,$N14)) -> Indicative | N14: =IF(ROWS($N$10:N14)>$C$7,"",SMALL('ALL ITEMS'!$M$3:$M$764,ROWS($N$10:N14))) -> 408
A15: =IF($N15="","",ROWS($N$10:N15)) -> 6 | B15: =IF($N15="","",INDEX('ALL ITEMS'!$B:$B,$N15)) -> CL-003 | C15: =IF($N15="","",INDEX('ALL ITEMS'!$A:$A,$N15)) -> Cladding, ACP & Facade Panels | D15: =IF($N15="","",INDEX('ALL ITEMS'!$D:$D,$N15)) -> Aluminium composite panel - A2 non-combustible | E15: =IF($N15="","",INDEX('ALL ITEMS'!$E:$E,$N15)) -> 4 mm, 0.5 mm skin | F15: =IF($N15="","",INDEX('ALL ITEMS'!$F:$F,$N15)) -> PVDF | G15: =IF($N15="","",INDEX('ALL ITEMS'!$G:$G,$N15)) -> Alubond / Alucobond / Equiv. | H15: =IF($N15="","",INDEX('ALL ITEMS'!$H:$H,$N15)) -> m2 | I15: =IF($N15="","",INDEX('ALL ITEMS'!$I:$I,$N15)) -> 121 | J15: =IF($N15="","",INDEX('ALL ITEMS'!$J:$J,$N15)) -> 145.2 | K15: =IF($N15="","",INDEX('ALL ITEMS'!$K:$K,$N15)) -> 152.46 | L15: =IF($N15="","",INDEX('ALL ITEMS'!$L:$L,$N15)) -> Indicative | N15: =IF(ROWS($N$10:N15)>$C$7,"",SMALL('ALL ITEMS'!$M$3:$M$764,ROWS($N$10:N15))) -> 409
A16: =IF($N16="","",ROWS($N$10:N16)) -> 7 | B16: =IF($N16="","",INDEX('ALL ITEMS'!$B:$B,$N16)) -> CL-010 | C16: =IF($N16="","",INDEX('ALL ITEMS'!$A:$A,$N16)) -> Cladding, ACP & Facade Panels | D16: =IF($N16="","",INDEX('ALL ITEMS'!$D:$D,$N16)) -> Aluminium corrugated / profiled sheet | E16: =IF($N16="","",INDEX('ALL ITEMS'!$E:$E,$N16)) -> 0.7 mm | F16: =IF($N16="","",INDEX('ALL ITEMS'!$F:$F,$N16)) -> PC / PVDF | G16: =IF($N16="","",INDEX('ALL ITEMS'!$G:$G,$N16)) -> Local | H16: =IF($N16="","",INDEX('ALL ITEMS'!$H:$H,$N16)) -> m2 | I16: =IF($N16="","",INDEX('ALL ITEMS'!$I:$I,$N16)) -> 71.5 | J16: =IF($N16="","",INDEX('ALL ITEMS'!$J:$J,$N16)) -> 85.8 | K16: =IF($N16="","",INDEX('ALL ITEMS'!$K:$K,$N16)) -> 90.09 | L16: =IF($N16="","",INDEX('ALL ITEMS'!$L:$L,$N16)) -> Indicative | N16: =IF(ROWS($N$10:N16)>$C$7,"",SMALL('ALL ITEMS'!$M$3:$M$764,ROWS($N$10:N16))) -> 416
A17: =IF($N17="","",ROWS($N$10:N17)) -> 8 | B17: =IF($N17="","",INDEX('ALL ITEMS'!$B:$B,$N17)) -> SI-045 | C17: =IF($N17="","",INDEX('ALL ITEMS'!$A:$A,$N17)) -> Finished Systems - Budget Supply & Install Rates | D17: =IF($N17="","",INDEX('ALL ITEMS'!$D:$D,$N17)) -> Polycarbonate canopy on MS / aluminium frame | E17: =IF($N17="","",INDEX('ALL ITEMS'!$E:$E,$N17)) -> 10 mm multiwall | F17: =IF($N17="","",INDEX('ALL ITEMS'!$F:$F,$N17)) -> PC | G17: =IF($N17="","",INDEX('ALL ITEMS'!$G:$G,$N17)) -> Local | H17: =IF($N17="","",INDEX('ALL ITEMS'!$H:$H,$N17)) -> m2 | I17: =IF($N17="","",INDEX('ALL ITEMS'!$I:$I,$N17)) -> 380 | J17: =IF($N17="","",INDEX('ALL ITEMS'!$J:$J,$N17)) -> 456 | K17: =IF($N17="","",INDEX('ALL ITEMS'!$K:$K,$N17)) -> 478.8 | L17: =IF($N17="","",INDEX('ALL ITEMS'!$L:$L,$N17)) -> Indicative | N17: =IF(ROWS($N$10:N17)>$C$7,"",SMALL('ALL ITEMS'!$M$3:$M$764,ROWS($N$10:N17))) -> 738
A18: =IF($N18="","",ROWS($N$10:N18)) | B18: =IF($N18="","",INDEX('ALL ITEMS'!$B:$B,$N18)) | C18: =IF($N18="","",INDEX('ALL ITEMS'!$A:$A,$N18)) | D18: =IF($N18="","",INDEX('ALL ITEMS'!$D:$D,$N18)) | E18: =IF($N18="","",INDEX('ALL ITEMS'!$E:$E,$N18)) | F18: =IF($N18="","",INDEX('ALL ITEMS'!$F:$F,$N18)) | G18: =IF($N18="","",INDEX('ALL ITEMS'!$G:$G,$N18)) | H18: =IF($N18="","",INDEX('ALL ITEMS'!$H:$H,$N18)) | I18: =IF($N18="","",INDEX('ALL ITEMS'!$I:$I,$N18)) | J18: =IF($N18="","",INDEX('ALL ITEMS'!$J:$J,$N18)) | K18: =IF($N18="","",INDEX('ALL ITEMS'!$K:$K,$N18)) | L18: =IF($N18="","",INDEX('ALL ITEMS'!$L:$L,$N18)) | N18: =IF(ROWS($N$10:N18)>$C$7,"",SMALL('ALL ITEMS'!$M$3:$M$764,ROWS($N$10:N18)))
A19: =IF($N19="","",ROWS($N$10:N19)) | B19: =IF($N19="","",INDEX('ALL ITEMS'!$B:$B,$N19)) | C19: =IF($N19="","",INDEX('ALL ITEMS'!$A:$A,$N19)) | D19: =IF($N19="","",INDEX('ALL ITEMS'!$D:$D,$N19)) | E19: =IF($N19="","",INDEX('ALL ITEMS'!$E:$E,$N19)) | F19: =IF($N19="","",INDEX('ALL ITEMS'!$F:$F,$N19)) | G19: =IF($N19="","",INDEX('ALL ITEMS'!$G:$G,$N19)) | H19: =IF($N19="","",INDEX('ALL ITEMS'!$H:$H,$N19)) | I19: =IF($N19="","",INDEX('ALL ITEMS'!$I:$I,$N19)) | J19: =IF($N19="","",INDEX('ALL ITEMS'!$J:$J,$N19)) | K19: =IF($N19="","",INDEX('ALL ITEMS'!$K:$K,$N19)) | L19: =IF($N19="","",INDEX('ALL ITEMS'!$L:$L,$N19)) | N19: =IF(ROWS($N$10:N19)>$C$7,"",SMALL('ALL ITEMS'!$M$3:$M$764,ROWS($N$10:N19)))
A20: =IF($N20="","",ROWS($N$10:N20)) | B20: =IF($N20="","",INDEX('ALL ITEMS'!$B:$B,$N20)) | C20: =IF($N20="","",INDEX('ALL ITEMS'!$A:$A,$N20)) | D20: =IF($N20="","",INDEX('ALL ITEMS'!$D:$D,$N20)) | E20: =IF($N20="","",INDEX('ALL ITEMS'!$E:$E,$N20)) | F20: =IF($N20="","",INDEX('ALL ITEMS'!$F:$F,$N20)) | G20: =IF($N20="","",INDEX('ALL ITEMS'!$G:$G,$N20)) | H20: =IF($N20="","",INDEX('ALL ITEMS'!$H:$H,$N20)) | I20: =IF($N20="","",INDEX('ALL ITEMS'!$I:$I,$N20)) | J20: =IF($N20="","",INDEX('ALL ITEMS'!$J:$J,$N20)) | K20: =IF($N20="","",INDEX('ALL ITEMS'!$K:$K,$N20)) | L20: =IF($N20="","",INDEX('ALL ITEMS'!$L:$L,$N20)) | N20: =IF(ROWS($N$10:N20)>$C$7,"",SMALL('ALL ITEMS'!$M$3:$M$764,ROWS($N$10:N20)))
A21: =IF($N21="","",ROWS($N$10:N21)) | B21: =IF($N21="","",INDEX('ALL ITEMS'!$B:$B,$N21)) | C21: =IF($N21="","",INDEX('ALL ITEMS'!$A:$A,$N21)) | D21: =IF($N21="","",INDEX('ALL ITEMS'!$D:$D,$N21)) | E21: =IF($N21="","",INDEX('ALL ITEMS'!$E:$E,$N21)) | F21: =IF($N21="","",INDEX('ALL ITEMS'!$F:$F,$N21)) | G21: =IF($N21="","",INDEX('ALL ITEMS'!$G:$G,$N21)) | H21: =IF($N21="","",INDEX('ALL ITEMS'!$H:$H,$N21)) | I21: =IF($N21="","",INDEX('ALL ITEMS'!$I:$I,$N21)) | J21: =IF($N21="","",INDEX('ALL ITEMS'!$J:$J,$N21)) | K21: =IF($N21="","",INDEX('ALL ITEMS'!$K:$K,$N21)) | L21: =IF($N21="","",INDEX('ALL ITEMS'!$L:$L,$N21)) | N21: =IF(ROWS($N$10:N21)>$C$7,"",SMALL('ALL ITEMS'!$M$3:$M$764,ROWS($N$10:N21)))
A22: =IF($N22="","",ROWS($N$10:N22)) | B22: =IF($N22="","",INDEX('ALL ITEMS'!$B:$B,$N22)) | C22: =IF($N22="","",INDEX('ALL ITEMS'!$A:$A,$N22)) | D22: =IF($N22="","",INDEX('ALL ITEMS'!$D:$D,$N22)) | E22: =IF($N22="","",INDEX('ALL ITEMS'!$E:$E,$N22)) | F22: =IF($N22="","",INDEX('ALL ITEMS'!$F:$F,$N22)) | G22: =IF($N22="","",INDEX('ALL ITEMS'!$G:$G,$N22)) | H22: =IF($N22="","",INDEX('ALL ITEMS'!$H:$H,$N22)) | I22: =IF($N22="","",INDEX('ALL ITEMS'!$I:$I,$N22)) | J22: =IF($N22="","",INDEX('ALL ITEMS'!$J:$J,$N22)) | K22: =IF($N22="","",INDEX('ALL ITEMS'!$K:$K,$N22)) | L22: =IF($N22="","",INDEX('ALL ITEMS'!$L:$L,$N22)) | N22: =IF(ROWS($N$10:N22)>$C$7,"",SMALL('ALL ITEMS'!$M$3:$M$764,ROWS($N$10:N22)))
... A309: =IF($N309="","",ROWS($N$10:N309)) | B309: =IF($N309="","",INDEX('ALL ITEMS'!$B:$B,$N309)) | C309: =IF($N309="","",INDEX('ALL ITEMS'!$A:$A,$N309)) | D309: =IF($N309="","",INDEX('ALL ITEMS'!$D:$D,$N309)) | E309: =IF($N309="","",INDEX('ALL ITEMS'!$E:$E,$N309)) | F309: =IF($N309="","",INDEX('ALL ITEMS'!$F:$F,$N309)) | G309: =IF($N309="","",INDEX('ALL ITEMS'!$G:$G,$N309)) | H309: =IF($N309="","",INDEX('ALL ITEMS'!$H:$H,$N309)) | I309: =IF($N309="","",INDEX('ALL ITEMS'!$I:$I,$N309)) | J309: =IF($N309="","",INDEX('ALL ITEMS'!$J:$J,$N309)) | K309: =IF($N309="","",INDEX('ALL ITEMS'!$K:$K,$N309)) | L309: =IF($N309="","",INDEX('ALL ITEMS'!$L:$L,$N309)) | N309: =IF(ROWS($N$10:N309)>$C$7,"",SMALL('ALL ITEMS'!$M$3:$M$764,ROWS($N$10:N309)))

Sheet ALL ITEMS
A1: ALL ITEMS - MASTER LIST (auto-linked from category sheets; do not edit here)
A2: Category | B2: Item Code | C2: Sub-Category | D2: Item Description | E2: Specification / Size | F2: Finish / Colour | G2: Brand / Origin | H2: Unit | I2: Net Cost (AED) | J2: Selling (AED) | K2: Selling incl. VAT | L2: Rate Status | M2: Search key
A3: =IF('01 Aluminium'!$C$5="","","Aluminium Profiles & Systems") -> Aluminium Profiles & Systems | B3: =IF('01 Aluminium'!$C$5="","",'01 Aluminium'!A5) -> AL-001 | C3: =IF('01 Aluminium'!$C$5="","",'01 Aluminium'!B5) -> Extrusions (per kg) | D3: =IF('01 Aluminium'!$C$5="","",'01 Aluminium'!C5) -> Aluminium extrusion | E3: =IF('01 Aluminium'!$C$5="","",'01 Aluminium'!D5) -> Alloy 6063-T5/T6 | F3: =IF('01 Aluminium'!$C$5="","",'01 Aluminium'!E5) -> Mill finish | G3: =IF('01 Aluminium'!$C$5="","",'01 Aluminium'!F5) -> Gulf Extrusions / Equiv. | H3: =IF('01 Aluminium'!$C$5="","",'01 Aluminium'!G5) -> kg | I3: =IF('01 Aluminium'!$C$5="","",'01 Aluminium'!J5) -> 16.28 | J3: =IF('01 Aluminium'!$C$5="","",'01 Aluminium'!K5) -> 19.54 | K3: =IF('01 Aluminium'!$C$5="","",'01 Aluminium'!L5) -> 20.52 | L3: =IF('01 Aluminium'!$C$5="","",'01 Aluminium'!M5) -> Indicative | M3: =IF(D3="","",IF(AND(OR(Search!$C$6="All Categories",A3=Search!$C$6),OR(Search!$P$5="",ISNUMBER(SEARCH(" "&Search!$P$5,N3))),OR(Search!$P$6="",ISNUMBER(SEARCH(" "&Search!$P$6,N3))),OR(Search!$P$7="",ISNUMBER(SEARCH(" "&Search!$P$7,N3))),OR(Search!$P$8="",ISNUMBER(SEARCH(" "&Search!$P$8,N3))),OR(Search!$P$9="",ISNUMBER(SEARCH(" "&Search!$P$9,N3))),OR(Search!$P$10="",ISNUMBER(SEARCH(" "&Search!$P$10,N3)))),ROW(),"")) | N3: =IF(D3="",""," "&SUBSTITUTE(SUBSTITUTE(SUBSTITUTE(SUBSTITUTE(SUBSTITUTE(SUBSTITUTE(SUBSTITUTE(B3&" "&C3&" "&D3&" "&E3&" "&F3&" "&G3&" "&H3&" "&'01 Aluminium'!R5,"("," "),")"," "),"/"," "),"-"," "),","," "),";"," "),":"," ")&" ") -> AL 001 Extrusions per kg Aluminium extrusion Alloy 6063 T5 T6 Mill finish Gulf Extrusions Equiv. kg aluminum alu
A4: =IF('01 Aluminium'!$C$6="","","Aluminium Profiles & Systems") -> Aluminium Profiles & Systems | B4: =IF('01 Aluminium'!$C$6="","",'01 Aluminium'!A6) -> AL-002 | C4: =IF('01 Aluminium'!$C$6="","",'01 Aluminium'!B6) -> Extrusions (per kg) | D4: =IF('01 Aluminium'!$C$6="","",'01 Aluminium'!C6) -> Aluminium extrusion | E4: =IF('01 Aluminium'!$C$6="","",'01 Aluminium'!D6) -> Alloy 6063-T5/T6 | F4: =IF('01 Aluminium'!$C$6="","",'01 Aluminium'!E6) -> Powder coated (RAL) | G4: =IF('01 Aluminium'!$C$6="","",'01 Aluminium'!F6) -> Gulf Extrusions / Equiv. | H4: =IF('01 Aluminium'!$C$6="","",'01 Aluminium'!G6) -> kg | I4: =IF('01 Aluminium'!$C$6="","",'01 Aluminium'!J6) -> 19.43 | J4: =IF('01 Aluminium'!$C$6="","",'01 Aluminium'!K6) -> 23.32 | K4: =IF('01 Aluminium'!$C$6="","",'01 Aluminium'!L6) -> 24.49 | L4: =IF('01 Aluminium'!$C$6="","",'01 Aluminium'!M6) -> Indicative | M4: =IF(D4="","",IF(AND(OR(Search!$C$6="All Categories",A4=Search!$C$6),OR(Search!$P$5="",ISNUMBER(SEARCH(" "&Search!$P$5,N4))),OR(Search!$P$6="",ISNUMBER(SEARCH(" "&Search!$P$6,N4))),OR(Search!$P$7="",ISNUMBER(SEARCH(" "&Search!$P$7,N4))),OR(Search!$P$8="",ISNUMBER(SEARCH(" "&Search!$P$8,N4))),OR(Search!$P$9="",ISNUMBER(SEARCH(" "&Search!$P$9,N4))),OR(Search!$P$10="",ISNUMBER(SEARCH(" "&Search!$P$10,N4)))),ROW(),"")) | N4: =IF(D4="",""," "&SUBSTITUTE(SUBSTITUTE(SUBSTITUTE(SUBSTITUTE(SUBSTITUTE(SUBSTITUTE(SUBSTITUTE(B4&" "&C4&" "&D4&" "&E4&" "&F4&" "&G4&" "&H4&" "&'01 Aluminium'!R6,"("," "),")"," "),"/"," "),"-"," "),","," "),";"," "),":"," ")&" ") -> AL 002 Extrusions per kg Aluminium extrusion Alloy 6063 T5 T6 Powder coated RAL Gulf Extrusions Equiv. kg aluminum alu pc
A5: =IF('01 Aluminium'!$C$7="","","Aluminium Profiles & Systems") -> Aluminium Profiles & Systems | B5: =IF('01 Aluminium'!$C$7="","",'01 Aluminium'!A7) -> AL-003 | C5: =IF('01 Aluminium'!$C$7="","",'01 Aluminium'!B7) -> Extrusions (per kg) | D5: =IF('01 Aluminium'!$C$7="","",'01 Aluminium'!C7) -> Aluminium extrusion | E5: =IF('01 Aluminium'!$C$7="","",'01 Aluminium'!D7) -> Alloy 6063-T5/T6 | F5: =IF('01 Aluminium'!$C$7="","",'01 Aluminium'!E7) -> Anodized 15-20 micron | G5: =IF('01 Aluminium'!$C$7="","",'01 Aluminium'!F7) -> Gulf Extrusions / Equiv. | H5: =IF('01 Aluminium'!$C$7="","",'01 Aluminium'!G7) -> kg | I5: =IF('01 Aluminium'!$C$7="","",'01 Aluminium'!J7) -> 21.53 | J5: =IF('01 Aluminium'!$C$7="","",'01 Aluminium'!K7) -> 25.84 | K5: =IF('01 Aluminium'!$C$7="","",'01 Aluminium'!L7) -> 27.13 | L5: =IF('01 Aluminium'!$C$7="","",'01 Aluminium'!M7) -> Indicative | M5: =IF(D5="","",IF(AND(OR(Search!$C$6="All Categories",A5=Search!$C$6),OR(Search!$P$5="",ISNUMBER(SEARCH(" "&Search!$P$5,N5))),OR(Search!$P$6="",ISNUMBER(SEARCH(" "&Search!$P$6,N5))),OR(Search!$P$7="",ISNUMBER(SEARCH(" "&Search!$P$7,N5))),OR(Search!$P$8="",ISNUMBER(SEARCH(" "&Search!$P$8,N5))),OR(Search!$P$9="",ISNUMBER(SEARCH(" "&Search!$P$9,N5))),OR(Search!$P$10="",ISNUMBER(SEARCH(" "&Search!$P$10,N5)))),ROW(),"")) | N5: =IF(D5="",""," "&SUBSTITUTE(SUBSTITUTE(SUBSTITUTE(SUBSTITUTE(SUBSTITUTE(SUBSTITUTE(SUBSTITUTE(B5&" "&C5&" "&D5&" "&E5&" "&F5&" "&G5&" "&H5&" "&'01 Aluminium'!R7,"("," "),")"," "),"/"," "),"-"," "),","," "),";"," "),":"," ")&" ") -> AL 003 Extrusions per kg Aluminium extrusion Alloy 6063 T5 T6 Anodized 15 20 micron Gulf Extrusions Equiv. kg aluminum alu
A6: =IF('01 Aluminium'!$C$8="","","Aluminium Profiles & Systems") -> Aluminium Profiles & Systems | B6: =IF('01 Aluminium'!$C$8="","",'01 Aluminium'!A8) -> AL-004 | C6: =IF('01 Aluminium'!$C$8="","",'01 Aluminium'!B8) -> Extrusions (per kg) | D6: =IF('01 Aluminium'!$C$8="","",'01 Aluminium'!C8) -> Aluminium extrusion | E6: =IF('01 Aluminium'!$C$8="","",'01 Aluminium'!D8) -> Alloy 6063-T5/T6 | F6: =IF('01 Aluminium'!$C$8="","",'01 Aluminium'!E8) -> PVDF 2/3-coat | G6: =IF('01 Aluminium'!$C$8="","",'01 Aluminium'!F8) -> Gulf Extrusions / Equiv. | H6: =IF('01 Aluminium'!$C$8="","",'01 Aluminium'!G8) -> kg | I6: =IF('01 Aluminium'!$C$8="","",'01 Aluminium'!J8) -> 25.2 | J6: =IF('01 Aluminium'!$C$8="","",'01 Aluminium'!K8) -> 30.24 | K6: =IF('01 Aluminium'!$C$8="","",'01 Aluminium'!L8) -> 31.75 | L6: =IF('01 Aluminium'!$C$8="","",'01 Aluminium'!M8) -> Indicative | M6: =IF(D6="","",IF(AND(OR(Search!$C$6="All Categories",A6=Search!$C$6),OR(Search!$P$5="",ISNUMBER(SEARCH(" "&Search!$P$5,N6))),OR(Search!$P$6="",ISNUMBER(SEARCH(" "&Search!$P$6,N6))),OR(Search!$P$7="",ISNUMBER(SEARCH(" "&Search!$P$7,N6))),OR(Search!$P$8="",ISNUMBER(SEARCH(" "&Search!$P$8,N6))),OR(Search!$P$9="",ISNUMBER(SEARCH(" "&Search!$P$9,N6))),OR(Search!$P$10="",ISNUMBER(SEARCH(" "&Search!$P$10,N6)))),ROW(),"")) | N6: =IF(D6="",""," "&SUBSTITUTE(SUBSTITUTE(SUBSTITUTE(SUBSTITUTE(SUBSTITUTE(SUBSTITUTE(SUBSTITUTE(B6&" "&C6&" "&D6&" "&E6&" "&F6&" "&G6&" "&H6&" "&'01 Aluminium'!R8,"("," "),")"," "),"/"," "),"-"," "),","," "),";"," "),":"," ")&" ") -> AL 004 Extrusions per kg Aluminium extrusion Alloy 6063 T5 T6 PVDF 2 3 coat Gulf Extrusions Equiv. kg aluminum alu
A7: =IF('01 Aluminium'!$C$9="","","Aluminium Profiles & Systems") -> Aluminium Profiles & Systems | B7: =IF('01 Aluminium'!$C$9="","",'01 Aluminium'!A9) -> AL-005 | C7: =IF('01 Aluminium'!$C$9="","",'01 Aluminium'!B9) -> Extrusions (per kg) | D7: =IF('01 Aluminium'!$C$9="","",'01 Aluminium'!C9) -> Aluminium extrusion | E7: =IF('01 Aluminium'!$C$9="","",'01 Aluminium'!D9) -> Alloy 6063-T5/T6 | F7: =IF('01 Aluminium'!$C$9="","",'01 Aluminium'!E9) -> Wood-grain finish | G7: =IF('01 Aluminium'!$C$9="","",'01 Aluminium'!F9) -> Gulf Extrusions / Equiv. | H7: =IF('01 Aluminium'!$C$9="","",'01 Aluminium'!G9) -> kg | I7: =IF('01 Aluminium'!$C$9="","",'01 Aluminium'!J9) -> 26.25 | J7: =IF('01 Aluminium'!$C$9="","",'01 Aluminium'!K9) -> 31.5 | K7: =IF('01 Aluminium'!$C$9="","",'01 Aluminium'!L9) -> 33.08 | L7: =IF('01 Aluminium'!$C$9="","",'01 Aluminium'!M9) -> Indicative | M7: =IF(D7="","",IF(AND(OR(Search!$C$6="All Categories",A7=Search!$C$6),OR(Search!$P$5="",ISNUMBER(SEARCH(" "&Search!$P$5,N7))),OR(Search!$P$6="",ISNUMBER(SEARCH(" "&Search!$P$6,N7))),OR(Search!$P$7="",ISNUMBER(SEARCH(" "&Search!$P$7,N7))),OR(Search!$P$8="",ISNUMBER(SEARCH(" "&Search!$P$8,N7))),OR(Search!$P$9="",ISNUMBER(SEARCH(" "&Search!$P$9,N7))),OR(Search!$P$10="",ISNUMBER(SEARCH(" "&Search!$P$10,N7)))),ROW(),"")) | N7: =IF(D7="",""," "&SUBSTITUTE(SUBSTITUTE(SUBSTITUTE(SUBSTITUTE(SUBSTITUTE(SUBSTITUTE(SUBSTITUTE(B7&" "&C7&" "&D7&" "&E7&" "&F7&" "&G7&" "&H7&" "&'01 Aluminium'!R9,"("," "),")"," "),"/"," "),"-"," "),","," "),";"," "),":"," ")&" ") -> AL 005 Extrusions per kg Aluminium extrusion Alloy 6063 T5 T6 Wood grain finish Gulf Extrusions Equiv. kg aluminum alu
A8: =IF('01 Aluminium'!$C$10="","","Aluminium Profiles & Systems") -> Aluminium Profiles & Systems | B8: =IF('01 Aluminium'!$C$10="","",'01 Aluminium'!A10) -> AL-006 | C8: =IF('01 Aluminium'!$C$10="","",'01 Aluminium'!B10) -> Extrusions (per kg) | D8: =IF('01 Aluminium'!$C$10="","",'01 Aluminium'!C10) -> Thermal-break aluminium extrusion | E8: =IF('01 Aluminium'!$C$10="","",'01 Aluminium'!D10) -> With polyamide strips | F8: =IF('01 Aluminium'!$C$10="","",'01 Aluminium'!E10) -> Powder coated | G8: =IF('01 Aluminium'!$C$10="","",'01 Aluminium'!F10) -> Gulf Extrusions / Equiv. | H8: =IF('01 Aluminium'!$C$10="","",'01 Aluminium'!G10) -> kg | I8: =IF('01 Aluminium'!$C$10="","",'01 Aluminium'!J10) -> 25.73 | J8: =IF('01 Aluminium'!$C$10="","",'01 Aluminium'!K10) -> 30.88 | K8: =IF('01 Aluminium'!$C$10="","",'01 Aluminium'!L10) -> 32.42 | L8: =IF('01 Aluminium'!$C$10="","",'01 Aluminium'!M10) -> Indicative | M8: =IF(D8="","",IF(AND(OR(Search!$C$6="All Categories",A8=Search!$C$6),OR(Search!$P$5="",ISNUMBER(SEARCH(" "&Search!$P$5,N8))),OR(Search!$P$6="",ISNUMBER(SEARCH(" "&Search!$P$6,N8))),OR(Search!$P$7="",ISNUMBER(SEARCH(" "&Search!$P$7,N8))),OR(Search!$P$8="",ISNUMBER(SEARCH(" "&Search!$P$8,N8))),OR(Search!$P$9="",ISNUMBER(SEARCH(" "&Search!$P$9,N8))),OR(Search!$P$10="",ISNUMBER(SEARCH(" "&Search!$P$10,N8)))),ROW(),"")) | N8: =IF(D8="",""," "&SUBSTITUTE(SUBSTITUTE(SUBSTITUTE(SUBSTITUTE(SUBSTITUTE(SUBSTITUTE(SUBSTITUTE(B8&" "&C8&" "&D8&" "&E8&" "&F8&" "&G8&" "&H8&" "&'01 Aluminium'!R10,"("," "),")"," "),"/"," "),"-"," "),","," "),";"," "),":"," ")&" ") -> AL 006 Extrusions per kg Thermal break aluminium extrusion With polyamide strips Powder coated Gulf Extrusions Equiv. kg aluminum alu pc
A9: =IF('01 Aluminium'!$C$11="","","Aluminium Profiles & Systems") -> Aluminium Profiles & Systems | B9: =IF('01 Aluminium'!$C$11="","",'01 Aluminium'!A11) -> AL-007 | C9: =IF('01 Aluminium'!$C$11="","",'01 Aluminium'!B11) -> Standard Sections | D9: =IF('01 Aluminium'!$C$11="","",'01 Aluminium'!C11) -> Aluminium square tube | E9: =IF('01 Aluminium'!$C$11="","",'01 Aluminium'!D11) -> 25 x 25 x 1.5 mm (0.38 kg/m) | F9: =IF('01 Aluminium'!$C$11="","",'01 Aluminium'!E11) -> Powder coated | G9: =IF('01 Aluminium'!$C$11="","",'01 Aluminium'!F11) -> Local | H9: =IF('01 Aluminium'!$C$11="","",'01 Aluminium'!G11) -> lm | I9: =IF('01 Aluminium'!$C$11="","",'01 Aluminium'!J11) -> 7.38 | J9: =IF('01 Aluminium'!$C$11="","",'01 Aluminium'!K11) -> 8.86 | K9: =IF('01 Aluminium'!$C$11="","",'01 Aluminium'!L11) -> 9.3 | L9: =IF('01 Aluminium'!$C$11="","",'01 Aluminium'!M11) -> Indicative | M9: =IF(D9="","",IF(AND(OR(Search!$C$6="All Categories",A9=Search!$C$6),OR(Search!$P$5="",ISNUMBER(SEARCH(" "&Search!$P$5,N9))),OR(Search!$P$6="",ISNUMBER(SEARCH(" "&Search!$P$6,N9))),OR(Search!$P$7="",ISNUMBER(SEARCH(" "&Search!$P$7,N9))),OR(Search!$P$8="",ISNUMBER(SEARCH(" "&Search!$P$8,N9))),OR(Search!$P$9="",ISNUMBER(SEARCH(" "&Search!$P$9,N9))),OR(Search!$P$10="",ISNUMBER(SEARCH(" "&Search!$P$10,N9)))),ROW(),"")) | N9: =IF(D9="",""," "&SUBSTITUTE(SUBSTITUTE(SUBSTITUTE(SUBSTITUTE(SUBSTITUTE(SUBSTITUTE(SUBSTITUTE(B9&" "&C9&" "&D9&" "&E9&" "&F9&" "&G9&" "&H9&" "&'01 Aluminium'!R11,"("," "),")"," "),"/"," "),"-"," "),","," "),";"," "),":"," ")&" ") -> AL 007 Standard Sections Aluminium square tube 25 x 25 x 1.5 mm 0.38 kg m Powder coated Local lm 25x25 25x25x1.5 1.5mm pipe box aluminum alu pc
A10: =IF('01 Aluminium'!$C$12="","","Aluminium Profiles & Systems") -> Aluminium Profiles & Systems | B10: =IF('01 Aluminium'!$C$12="","",'01 Aluminium'!A12) -> AL-008 | C10: =IF('01 Aluminium'!$C$12="","",'01 Aluminium'!B12) -> Standard Sections | D10: =IF('01 Aluminium'!$C$12="","",'01 Aluminium'!C12) -> Aluminium square tube | E10: =IF('01 Aluminium'!$C$12="","",'01 Aluminium'!D12) -> 40 x 40 x 2.0 mm (0.82 kg/m) | F10: =IF('01 Aluminium'!$C$12="","",'01 Aluminium'!E12) -> Powder coated | G10: =IF('01 Aluminium'!$C$12="","",'01 Aluminium'!F12) -> Local | H10: =IF('01 Aluminium'!$C$12="","",'01 Aluminium'!G12) -> lm | I10: =IF('01 Aluminium'!$C$12="","",'01 Aluminium'!J12) -> 15.93 | J10: =IF('01 Aluminium'!$C$12="","",'01 Aluminium'!K12) -> 19.12 | K10: =IF('01 Aluminium'!$C$12="","",'01 Aluminium'!L12) -> 20.08 | L10: =IF('01 Aluminium'!$C$12="","",'01 Aluminium'!M12) -> Indicative | M10: =IF(D10="","",IF(AND(OR(Search!$C$6="All Categories",A10=Search!$C$6),OR(Search!$P$5="",ISNUMBER(SEARCH(" "&Search!$P$5,N10))),OR(Search!$P$6="",ISNUMBER(SEARCH(" "&Search!$P$6,N10))),OR(Search!$P$7="",ISNUMBER(SEARCH(" "&Search!$P$7,N10))),OR(Search!$P$8="",ISNUMBER(SEARCH(" "&Search!$P$8,N10))),OR(Search!$P$9="",ISNUMBER(SEARCH(" "&Search!$P$9,N10))),OR(Search!$P$10="",ISNUMBER(SEARCH(" "&Search!$P$10,N10)))),ROW(),"")) | N10: =IF(D10="",""," "&SUBSTITUTE(SUBSTITUTE(SUBSTITUTE(SUBSTITUTE(SUBSTITUTE(SUBSTITUTE(SUBSTITUTE(B10&" "&C10&" "&D10&" "&E10&" "&F10&" "&G10&" "&H10&" "&'01 Aluminium'!R12,"("," "),")"," "),"/"," "),"-"," "),","," "),";"," "),":"," ")&" ") -> AL 008 Standard Sections Aluminium square tube 40 x 40 x 2.0 mm 0.82 kg m Powder coated Local lm 40x40 40x40x2.0 40x40x2 2.0mm pipe box aluminum alu pc
A11: =IF('01 Aluminium'!$C$13="","","Aluminium Profiles & Systems") -> Aluminium Profiles & Systems | B11: =IF('01 Aluminium'!$C$13="","",'01 Aluminium'!A13) -> AL-009 | C11: =IF('01 Aluminium'!$C$13="","",'01 Aluminium'!B13) -> Standard Sections | D11: =IF('01 Aluminium'!$C$13="","",'01 Aluminium'!C13) -> Aluminium square tube | E11: =IF('01 Aluminium'!$C$13="","",'01 Aluminium'!D13) -> 50 x 50 x 2.0 mm (1.04 kg/m) | F11: =IF('01 Aluminium'!$C$13="","",'01 Aluminium'!E13) -> Powder coated | G11: =IF('01 Aluminium'!$C$13="","",'01 Aluminium'!F13) -> Local | H11: =IF('01 Aluminium'!$C$13="","",'01 Aluminium'!G13) -> lm | I11: =IF('01 Aluminium'!$C$13="","",'01 Aluminium'!J13) -> 20.2 | J11: =IF('01 Aluminium'!$C$13="","",'01 Aluminium'!K13) -> 24.24 | K11: =IF('01 Aluminium'!$C$13="","",'01 Aluminium'!L13) -> 25.45 | L11: =IF('01 Aluminium'!$C$13="","",'01 Aluminium'!M13) -> Indicative | M11: =IF(D11="","",IF(AND(OR(Search!$C$6="All Categories",A11=Search!$C$6),OR(Search!$P$5="",ISNUMBER(SEARCH(" "&Search!$P$5,N11))),OR(Search!$P$6="",ISNUMBER(SEARCH(" "&Search!$P$6,N11))),OR(Search!$P$7="",ISNUMBER(SEARCH(" "&Search!$P$7,N11))),OR(Search!$P$8="",ISNUMBER(SEARCH(" "&Search!$P$8,N11))),OR(Search!$P$9="",ISNUMBER(SEARCH(" "&Search!$P$9,N11))),OR(Search!$P$10="",ISNUMBER(SEARCH(" "&Search!$P$10,N11)))),ROW(),"")) | N11: =IF(D11="",""," "&SUBSTITUTE(SUBSTITUTE(SUBSTITUTE(SUBSTITUTE(SUBSTITUTE(SUBSTITUTE(SUBSTITUTE(B11&" "&C11&" "&D11&" "&E11&" "&F11&" "&G11&" "&H11&" "&'01 Aluminium'!R13,"("," "),")"," "),"/"," "),"-"," "),","," "),";"," "),":"," ")&" ") -> AL 009 Standard Sections Aluminium square tube 50 x 50 x 2.0 mm 1.04 kg m Powder coated Local lm 50x50 50x50x2.0 50x50x2 2.0mm pipe box aluminum alu pc
A12: =IF('01 Aluminium'!$C$14="","","Aluminium Profiles & Systems") -> Aluminium Profiles & Systems | B12: =IF('01 Aluminium'!$C$14="","",'01 Aluminium'!A14) -> AL-010 | C12: =IF('01 Aluminium'!$C$14="","",'01 Aluminium'!B14) -> Standard Sections | D12: =IF('01 Aluminium'!$C$14="","",'01 Aluminium'!C14) -> Aluminium rectangular tube | E12: =IF('01 Aluminium'!$C$14="","",'01 Aluminium'!D14) -> 100 x 50 x 2.5 mm (1.96 kg/m) | F12: =IF('01 Aluminium'!$C$14="","",'01 Aluminium'!E14) -> Powder coated | G12: =IF('01 Aluminium'!$C$14="","",'01 Aluminium'!F14) -> Local | H12: =IF('01 Aluminium'!$C$14="","",'01 Aluminium'!G14) -> lm | I12: =IF('01 Aluminium'!$C$14="","",'01 Aluminium'!J14) -> 38.07 | J12: =IF('01 Aluminium'!$C$14="","",'01 Aluminium'!K14) -> 45.68 | K12: =IF('01 Aluminium'!$C$14="","",'01 Aluminium'!L14) -> 47.96 | L12: =IF('01 Aluminium'!$C$14="","",'01 Aluminium'!M14) -> Indicative | M12: =IF(D12="","",IF(AND(OR(Search!$C$6="All Categories",A12=Search!$C$6),OR(Search!$P$5="",ISNUMBER(SEARCH(" "&Search!$P$5,N12))),OR(Search!$P$6="",ISNUMBER(SEARCH(" "&Search!$P$6,N12))),OR(Search!$P$7="",ISNUMBER(SEARCH(" "&Search!$P$7,N12))),OR(Search!$P$8="",ISNUMBER(SEARCH(" "&Search!$P$8,N12))),OR(Search!$P$9="",ISNUMBER(SEARCH(" "&Search!$P$9,N12))),OR(Search!$P$10="",ISNUMBER(SEARCH(" "&Search!$P$10,N12)))),ROW(),"")) | N12: =IF(D12="",""," "&SUBSTITUTE(SUBSTITUTE(SUBSTITUTE(SUBSTITUTE(SUBSTITUTE(SUBSTITUTE(SUBSTITUTE(B12&" "&C12&" "&D12&" "&E12&" "&F12&" "&G12&" "&H12&" "&'01 Aluminium'!R14,"("," "),")"," "),"/"," "),"-"," "),","," "),";"," "),":"," ")&" ") -> AL 010 Standard Sections Aluminium rectangular tube 100 x 50 x 2.5 mm 1.96 kg m Powder coated Local lm 100x50 100x50x2.5 2.5mm pipe box aluminum alu pc
A13: =IF('01 Aluminium'!$C$15="","","Aluminium Profiles & Systems") -> Aluminium Profiles & Systems | B13: =IF('01 Aluminium'!$C$15="","",'01 Aluminium'!A15) -> AL-011 | C13: =IF('01 Aluminium'!$C$15="","",'01 Aluminium'!B15) -> Standard Sections | D13: =IF('01 Aluminium'!$C$15="","",'01 Aluminium'!C15) -> Aluminium rectangular tube | E13: =IF('01 Aluminium'!$C$15="","",'01 Aluminium'!D15) -> 100 x 50 x 3.0 mm (2.33 kg/m) | F13: =IF('01 Aluminium'!$C$15="","",'01 Aluminium'!E15) -> Powder coated | G13: =IF('01 Aluminium'!$C$15="","",'01 Aluminium'!F15) -> Local | H13: =IF('01 Aluminium'!$C$15="","",'01 Aluminium'!G15) -> lm | I13: =IF('01 Aluminium'!$C$15="","",'01 Aluminium'!J15) -> 45.27 | J13: =IF('01 Aluminium'!$C$15="","",'01 Aluminium'!K15) -> 54.32 | K13: =IF('01 Aluminium'!$C$15="","",'01 Aluminium'!L15) -> 57.04 | L13: =IF('01 Aluminium'!$C$15="","",'01 Aluminium'!M15) -> Indicative | M13: =IF(D13="","",IF(AND(OR(Search!$C$6="All Categories",A13=Search!$C$6),OR(Search!$P$5="",ISNUMBER(SEARCH(" "&Search!$P$5,N13))),OR(Search!$P$6="",ISNUMBER(SEARCH(" "&Search!$P$6,N13))),OR(Search!$P$7="",ISNUMBER(SEARCH(" "&Search!$P$7,N13))),OR(Search!$P$8="",ISNUMBER(SEARCH(" "&Search!$P$8,N13))),OR(Search!$P$9="",ISNUMBER(SEARCH(" "&Search!$P$9,N13))),OR(Search!$P$10="",ISNUMBER(SEARCH(" "&Search!$P$10,N13)))),ROW(),"")) | N13: =IF(D13="",""," "&SUBSTITUTE(SUBSTITUTE(SUBSTITUTE(SUBSTITUTE(SUBSTITUTE(SUBSTITUTE(SUBSTITUTE(B13&" "&C13&" "&D13&" "&E13&" "&F13&" "&G13&" "&H13&" "&'01 Aluminium'!R15,"("," "),")"," "),"/"," "),"-"," "),","," "),";"," "),":"," ")&" ") -> AL 011 Standard Sections Aluminium rectangular tube 100 x 50 x 3.0 mm 2.33 kg m Powder coated Local lm 100x50 100x50x3.0 100x50x3 3.0mm pipe box aluminum alu pc
A14: =IF('01 Aluminium'!$C$16="","","Aluminium Profiles & Systems") -> Aluminium Profiles & Systems | B14: =IF('01 Aluminium'!$C$16="","",'01 Aluminium'!A16) -> AL-012 | C14: =IF('01 Aluminium'!$C$16="","",'01 Aluminium'!B16) -> Standard Sections | D14: =IF('01 Aluminium'!$C$16="","",'01 Aluminium'!C16) -> Aluminium rectangular tube | E14: =IF('01 Aluminium'!$C$16="","",'01 Aluminium'!D16) -> 150 x 50 x 3.0 mm (3.14 kg/m) | F14: =IF('01 Aluminium'!$C$16="","",'01 Aluminium'!E16) -> Powder coated | G14: =IF('01 Aluminium'!$C$16="","",'01 Aluminium'!F16) -> Local | H14: =IF('01 Aluminium'!$C$16="","",'01 Aluminium'!G16) -> lm | I14: =IF('01 Aluminium'!$C$16="","",'01 Aluminium'!J16) -> 60.99 | J14: =IF('01 Aluminium'!$C$16="","",'01 Aluminium'!K16) -> 73.19 | K14: =IF('01 Aluminium'!$C$16="","",'01 Aluminium'!L16) -> 76.85 | L14: =IF('01 Aluminium'!$C$16="","",'01 Aluminium'!M16) -> Indicative | M14: =IF(D14="","",IF(AND(OR(Search!$C$6="All Categories",A14=Search!$C$6),OR(Search!$P$5="",ISNUMBER(SEARCH(" "&Search!$P$5,N14))),OR(Search!$P$6="",ISNUMBER(SEARCH(" "&Search!$P$6,N14))),OR(Search!$P$7="",ISNUMBER(SEARCH(" "&Search!$P$7,N14))),OR(Search!$P$8="",ISNUMBER(SEARCH(" "&Search!$P$8,N14))),OR(Search!$P$9="",ISNUMBER(SEARCH(" "&Search!$P$9,N14))),OR(Search!$P$10="",ISNUMBER(SEARCH(" "&Search!$P$10,N14)))),ROW(),"")) | N14: =IF(D14="",""," "&SUBSTITUTE(SUBSTITUTE(SUBSTITUTE(SUBSTITUTE(SUBSTITUTE(SUBSTITUTE(SUBSTITUTE(B14&" "&C14&" "&D14&" "&E14&" "&F14&" "&G14&" "&H14&" "&'01 Aluminium'!R16,"("," "),")"," "),"/"," "),"-"," "),","," "),";"," "),":"," ")&" ") -> AL 012 Standard Sections Aluminium rectangular tube 150 x 50 x 3.0 mm 3.14 kg m Powder coated Local lm 150x50 150x50x3.0 150x50x3 3.0mm pipe box aluminum alu pc
A15: =IF('01 Aluminium'!$C$17="","","Aluminium Profiles & Systems") -> Aluminium Profiles & Systems | B15: =IF('01 Aluminium'!$C$17="","",'01 Aluminium'!A17) -> AL-013 | C15: =IF('01 Aluminium'!$C$17="","",'01 Aluminium'!B17) -> Standard Sections | D15: =IF('01 Aluminium'!$C$17="","",'01 Aluminium'!C17) -> Aluminium rectangular tube | E15: =IF('01 Aluminium'!$C$17="","",'01 Aluminium'!D17) -> 200 x 50 x 3.0 mm (3.95 kg/m) | F15: =IF('01 Aluminium'!$C$17="","",'01 Aluminium'!E17) -> Powder coated | G15: =IF('01 Aluminium'!$C$17="","",'01 Aluminium'!F17) -> Local | H15: =IF('01 Aluminium'!$C$17="","",'01 Aluminium'!G17) -> lm | I15: =IF('01 Aluminium'!$C$17="","",'01 Aluminium'!J17) -> 76.73 | J15: =IF('01 Aluminium'!$C$17="","",'01 Aluminium'!K17) -> 92.08 | K15: =IF('01 Aluminium'!$C$17="","",'01 Aluminium'!L17) -> 96.68 | L15: =IF('01 Aluminium'!$C$17="","",'01 Aluminium'!M17) -> Indicative | M15: =IF(D15="","",IF(AND(OR(Search!$C$6="All Categories",A15=Search!$C$6),OR(Search!$P$5="",ISNUMBER(SEARCH(" "&Search!$P$5,N15))),OR(Search!$P$6="",ISNUMBER(SEARCH(" "&Search!$P$6,N15))),OR(Search!$P$7="",ISNUMBER(SEARCH(" "&Search!$P$7,N15))),OR(Search!$P$8="",ISNUMBER(SEARCH(" "&Search!$P$8,N15))),OR(Search!$P$9="",ISNUMBER(SEARCH(" "&Search!$P$9,N15))),OR(Search!$P$10="",ISNUMBER(SEARCH(" "&Search!$P$10,N15)))),ROW(),"")) | N15: =IF(D15="",""," "&SUBSTITUTE(SUBSTITUTE(SUBSTITUTE(SUBSTITUTE(SUBSTITUTE(SUBSTITUTE(SUBSTITUTE(B15&" "&C15&" "&D15&" "&E15&" "&F15&" "&G15&" "&H15&" "&'01 Aluminium'!R17,"("," "),")"," "),"/"," "),"-"," "),","," "),";"," "),":"," ")&" ") -> AL 013 Standard Sections Aluminium rectangular tube 200 x 50 x 3.0 mm 3.95 kg m Powder coated Local lm 200x50 200x50x3.0 200x50x3 3.0mm pipe box aluminum alu pc
A16: =IF('01 Aluminium'!$C$18="","","Aluminium Profiles & Systems") -> Aluminium Profiles & Systems | B16: =IF('01 Aluminium'!$C$18="","",'01 Aluminium'!A18) -> AL-014 | C16: =IF('01 Aluminium'!$C$18="","",'01 Aluminium'!B18) -> Standard Sections | D16: =IF('01 Aluminium'!$C$18="","",'01 Aluminium'!C18) -> Aluminium equal angle | E16: =IF('01 Aluminium'!$C$18="","",'01 Aluminium'!D18) -> 25 x 25 x 2.0 mm (0.26 kg/m) | F16: =IF('01 Aluminium'!$C$18="","",'01 Aluminium'!E18) -> Powder coated | G16: =IF('01 Aluminium'!$C$18="","",'01 Aluminium'!F18) -> Local | H16: =IF('01 Aluminium'!$C$18="","",'01 Aluminium'!G18) -> lm | I16: =IF('01 Aluminium'!$C$18="","",'01 Aluminium'!J18) -> 5.05 | J16: =IF('01 Aluminium'!$C$18="","",'01 Aluminium'!K18) -> 6.06 | K16: =IF('01 Aluminium'!$C$18="","",'01 Aluminium'!L18) -> 6.36 | L16: =IF('01 Aluminium'!$C$18="","",'01 Aluminium'!M18) -> Indicative | M16: =IF(D16="","",IF(AND(OR(Search!$C$6="All Categories",A16=Search!$C$6),OR(Search!$P$5="",ISNUMBER(SEARCH(" "&Search!$P$5,N16))),OR(Search!$P$6="",ISNUMBER(SEARCH(" "&Search!$P$6,N16))),OR(Search!$P$7="",ISNUMBER(SEARCH(" "&Search!$P$7,N16))),OR(Search!$P$8="",ISNUMBER(SEARCH(" "&Search!$P$8,N16))),OR(Search!$P$9="",ISNUMBER(SEARCH(" "&Search!$P$9,N16))),OR(Search!$P$10="",ISNUMBER(SEARCH(" "&Search!$P$10,N16)))),ROW(),"")) | N16: =IF(D16="",""," "&SUBSTITUTE(SUBSTITUTE(SUBSTITUTE(SUBSTITUTE(SUBSTITUTE(SUBSTITUTE(SUBSTITUTE(B16&" "&C16&" "&D16&" "&E16&" "&F16&" "&G16&" "&H16&" "&'01 Aluminium'!R18,"("," "),")"," "),"/"," "),"-"," "),","," "),";"," "),":"," ")&" ") -> AL 014 Standard Sections Aluminium equal angle 25 x 25 x 2.0 mm 0.26 kg m Powder coated Local lm 25x25 25x25x2.0 25x25x2 2.0mm aluminum alu pc angle l
A17: =IF('01 Aluminium'!$C$19="","","Aluminium Profiles & Systems") -> Aluminium Profiles & Systems | B17: =IF('01 Aluminium'!$C$19="","",'01 Aluminium'!A19) -> AL-015 | C17: =IF('01 Aluminium'!$C$19="","",'01 Aluminium'!B19) -> Standard Sections | D17: =IF('01 Aluminium'!$C$19="","",'01 Aluminium'!C19) -> Aluminium equal angle | E17: =IF('01 Aluminium'!$C$19="","",'01 Aluminium'!D19) -> 50 x 50 x 3.0 mm (0.79 kg/m) | F17: =IF('01 Aluminium'!$C$19="","",'01 Aluminium'!E19) -> Powder coated | G17: =IF('01 Aluminium'!$C$19="","",'01 Aluminium'!F19) -> Local | H17: =IF('01 Aluminium'!$C$19="","",'01 Aluminium'!G19) -> lm | I17: =IF('01 Aluminium'!$C$19="","",'01 Aluminium'!J19) -> 15.35 | J17: =IF('01 Aluminium'!$C$19="","",'01 Aluminium'!K19) -> 18.42 | K17: =IF('01 Aluminium'!$C$19="","",'01 Aluminium'!L19) -> 19.34 | L17: =IF('01 Aluminium'!$C$19="","",'01 Aluminium'!M19) -> Indicative | M17: =IF(D17="","",IF(AND(OR(Search!$C$6="All Categories",A17=Search!$C$6),OR(Search!$P$5="",ISNUMBER(SEARCH(" "&Search!$P$5,N17))),OR(Search!$P$6="",ISNUMBER(SEARCH(" "&Search!$P$6,N17))),OR(Search!$P$7="",ISNUMBER(SEARCH(" "&Search!$P$7,N17))),OR(Search!$P$8="",ISNUMBER(SEARCH(" "&Search!$P$8,N17))),OR(Search!$P$9="",ISNUMBER(SEARCH(" "&Search!$P$9,N17))),OR(Search!$P$10="",ISNUMBER(SEARCH(" "&Search!$P$10,N17)))),ROW(),"")) | N17: =IF(D17="",""," "&SUBSTITUTE(SUBSTITUTE(SUBSTITUTE(SUBSTITUTE(SUBSTITUTE(SUBSTITUTE(SUBSTITUTE(B17&" "&C17&" "&D17&" "&E17&" "&F17&" "&G17&" "&H17&" "&'01 Aluminium'!R19,"("," "),")"," "),"/"," "),"-"," "),","," "),";"," "),":"," ")&" ") -> AL 015 Standard Sections Aluminium equal angle 50 x 50 x 3.0 mm 0.79 kg m Powder coated Local lm 50x50 50x50x3.0 50x50x3 3.0mm aluminum alu pc angle l
A18: =IF('01 Aluminium'!$C$20="","","Aluminium Profiles & Systems") -> Aluminium Profiles & Systems | B18: =IF('01 Aluminium'!$C$20="","",'01 Aluminium'!A20) -> AL-016 | C18: =IF('01 Aluminium'!$C$20="","",'01 Aluminium'!B20) -> Standard Sections | D18: =IF('01 Aluminium'!$C$20="","",'01 Aluminium'!C20) -> Aluminium flat bar | E18: =IF('01 Aluminium'!$C$20="","",'01 Aluminium'!D20) -> 50 x 5 mm (0.68 kg/m) | F18: =IF('01 Aluminium'!$C$20="","",'01 Aluminium'!E20) -> Powder coated | G18: =IF('01 Aluminium'!$C$20="","",'01 Aluminium'!F20) -> Local | H18: =IF('01 Aluminium'!$C$20="","",'01 Aluminium'!G20) -> lm | I18: =IF('01 Aluminium'!$C$20="","",'01 Aluminium'!J20) -> 13.21 | J18: =IF('01 Aluminium'!$C$20="","",'01 Aluminium'!K20) -> 15.85 | K18: =IF('01 Aluminium'!$C$20="","",'01 Aluminium'!L20) -> 16.64 | L18: =IF('01 Aluminium'!$C$20="","",'01 Aluminium'!M20) -> Indicative | M18: =IF(D18="","",IF(AND(OR(Search!$C$6="All Categories",A18=Search!$C$6),OR(Search!$P$5="",ISNUMBER(SEARCH(" "&Search!$P$5,N18))),OR(Search!$P$6="",ISNUMBER(SEARCH(" "&Search!$P$6,N18))),OR(Search!$P$7="",ISNUMBER(SEARCH(" "&Search!$P$7,N18))),OR(Search!$P$8="",ISNUMBER(SEARCH(" "&Search!$P$8,N18))),OR(Search!$P$9="",ISNUMBER(SEARCH(" "&Search!$P$9,N18))),OR(Search!$P$10="",ISNUMBER(SEARCH(" "&Search!$P$10,N18)))),ROW(),"")) | N18: =IF(D18="",""," "&SUBSTITUTE(SUBSTITUTE(SUBSTITUTE(SUBSTITUTE(SUBSTITUTE(SUBSTITUTE(SUBSTITUTE(B18&" "&C18&" "&D18&" "&E18&" "&F18&" "&G18&" "&H18&" "&'01 Aluminium'!R20,"("," "),")"," "),"/"," "),"-"," "),","," "),";"," "),":"," ")&" ") -> AL 016 Standard Sections Aluminium flat bar 50 x 5 mm 0.68 kg m Powder coated Local lm 50x5 5mm aluminum alu pc patti strip
A19: =IF('01 Aluminium'!$C$21="","","Aluminium Profiles & Systems") -> Aluminium Profiles & Systems | B19: =IF('01 Aluminium'!$C$21="","",'01 Aluminium'!A21) -> AL-017 | C19: =IF('01 Aluminium'!$C$21="","",'01 Aluminium'!B21) -> Standard Sections | D19: =IF('01 Aluminium'!$C$21="","",'01 Aluminium'!C21) -> Aluminium flat bar | E19: =IF('01 Aluminium'!$C$21="","",'01 Aluminium'!D21) -> 100 x 6 mm (1.62 kg/m) | F19: =IF('01 Aluminium'!$C$21="","",'01 Aluminium'!E21) -> Powder coated | G19: =IF('01 Aluminium'!$C$21="","",'01 Aluminium'!F21) -> Local | H19: =IF('01 Aluminium'!$C$21="","",'01 Aluminium'!G21) -> lm | I19: =IF('01 Aluminium'!$C$21="","",'01 Aluminium'!J21) -> 31.47 | J19: =IF('01 Aluminium'!$C$21="","",'01 Aluminium'!K21) -> 37.76 | K19: =IF('01 Aluminium'!$C$21="","",'01 Aluminium'!L21) -> 39.65 | L19: =IF('01 Aluminium'!$C$21="","",'01 Aluminium'!M21) -> Indicative | M19: =IF(D19="","",IF(AND(OR(Search!$C$6="All Categories",A19=Search!$C$6),OR(Search!$P$5="",ISNUMBER(SEARCH(" "&Search!$P$5,N19))),OR(Search!$P$6="",ISNUMBER(SEARCH(" "&Search!$P$6,N19))),OR(Search!$P$7="",ISNUMBER(SEARCH(" "&Search!$P$7,N19))),OR(Search!$P$8="",ISNUMBER(SEARCH(" "&Search!$P$8,N19))),OR(Search!$P$9="",ISNUMBER(SEARCH(" "&Search!$P$9,N19))),OR(Search!$P$10="",ISNUMBER(SEARCH(" "&Search!$P$10,N19)))),ROW(),"")) | N19: =IF(D19="",""," "&SUBSTITUTE(SUBSTITUTE(SUBSTITUTE(SUBSTITUTE(SUBSTITUTE(SUBSTITUTE(SUBSTITUTE(B19&" "&C19&" "&D19&" "&E19&" "&F19&" "&G19&" "&H19&" "&'01 Aluminium'!R21,"("," "),")"," "),"/"," "),"-"," "),","," "),";"," "),":"," ")&" ") -> AL 017 Standard Sections Aluminium flat bar 100 x 6 mm 1.62 kg m Powder coated Local lm 100x6 6mm aluminum alu pc patti strip
A20: =IF('01 Aluminium'!$C$22="","","Aluminium Profiles & Systems") -> Aluminium Profiles & Systems | B20: =IF('01 Aluminium'!$C$22="","",'01 Aluminium'!A22) -> AL-018 | C20: =IF('01 Aluminium'!$C$22="","",'01 Aluminium'!B22) -> Standard Sections | D20: =IF('01 Aluminium'!$C$22="","",'01 Aluminium'!C22) -> Aluminium U-channel for glass | E20: =IF('01 Aluminium'!$C$22="","",'01 Aluminium'!D22) -> For 10-12 mm glass (0.45 kg/m) | F20: =IF('01 Aluminium'!$C$22="","",'01 Aluminium'!E22) -> Powder coated / anodized | G20: =IF('01 Aluminium'!$C$22="","",'01 Aluminium'!F22) -> Local | H20: =IF('01 Aluminium'!$C$22="","",'01 Aluminium'!G22) -> lm | I20: =IF('01 Aluminium'!$C$22="","",'01 Aluminium'!J22) -> 8.75 | J20: =IF('01 Aluminium'!$C$22="","",'01 Aluminium'!K22) -> 10.5 | K20: =IF('01 Aluminium'!$C$22="","",'01 Aluminium'!L22) -> 11.03 | L20: =IF('01 Aluminium'!$C$22="","",'01 Aluminium'!M22) -> Indicative | M20: =IF(D20="","",IF(AND(OR(Search!$C$6="All Categories",A20=Search!$C$6),OR(Search!$P$5="",ISNUMBER(SEARCH(" "&Search!$P$5,N20))),OR(Search!$P$6="",ISNUMBER(SEARCH(" "&Search!$P$6,N20))),OR(Search!$P$7="",ISNUMBER(SEARCH(" "&Search!$P$7,N20))),OR(Search!$P$8="",ISNUMBER(SEARCH(" "&Search!$P$8,N20))),OR(Search!$P$9="",ISNUMBER(SEARCH(" "&Search!$P$9,N20))),OR(Search!$P$10="",ISNUMBER(SEARCH(" "&Search!$P$10,N20)))),ROW(),"")) | N20: =IF(D20="",""," "&SUBSTITUTE(SUBSTITUTE(SUBSTITUTE(SUBSTITUTE(SUBSTITUTE(SUBSTITUTE(SUBSTITUTE(B20&" "&C20&" "&D20&" "&E20&" "&F20&" "&G20&" "&H20&" "&'01 Aluminium'!R22,"("," "),")"," "),"/"," "),"-"," "),","," "),";"," "),":"," ")&" ") -> AL 018 Standard Sections Aluminium U channel for glass For 10 12 mm glass 0.45 kg m Powder coated anodized Local lm 12mm aluminum alu pc stainless steel
A21: =IF('01 Aluminium'!$C$23="","","Aluminium Profiles & Systems") -> Aluminium Profiles & Systems | B21: =IF('01 Aluminium'!$C$23="","",'01 Aluminium'!A23) -> AL-019 | C21: =IF('01 Aluminium'!$C$23="","",'01 Aluminium'!B23) -> Standard Sections | D21: =IF('01 Aluminium'!$C$23="","",'01 Aluminium'!C23) -> Aluminium heavy U-channel (frameless partition) | E21: =IF('01 Aluminium'!$C$23="","",'01 Aluminium'!D23) -> 40 x 40 mm (0.90 kg/m) | F21: =IF('01 Aluminium'!$C$23="","",'01 Aluminium'!E23) -> Anodized / PC | G21: =IF('01 Aluminium'!$C$23="","",'01 Aluminium'!F23) -> Local | H21: =IF('01 Aluminium'!$C$23="","",'01 Aluminium'!G23) -> lm | I21: =IF('01 Aluminium'!$C$23="","",'01 Aluminium'!J23) -> 17.48 | J21: =IF('01 Aluminium'!$C$23="","",'01 Aluminium'!K23) -> 20.98 | K21: =IF('01 Aluminium'!$C$23="","",'01 Aluminium'!L23) -> 22.03 | L21: =IF('01 Aluminium'!$C$23="","",'01 Aluminium'!M23) -> Indicative | M21: =IF(D21="","",IF(AND(OR(Search!$C$6="All Categories",A21=Search!$C$6),OR(Search!$P$5="",ISNUMBER(SEARCH(" "&Search!$P$5,N21))),OR(Search!$P$6="",ISNUMBER(SEARCH(" "&Search!$P$6,N21))),OR(Search!$P$7="",ISNUMBER(SEARCH(" "&Search!$P$7,N21))),OR(Search!$P$8="",ISNUMBER(SEARCH(" "&Search!$P$8,N21))),OR(Search!$P$9="",ISNUMBER(SEARCH(" "&Search!$P$9,N21))),OR(Search!$P$10="",ISNUMBER(SEARCH(" "&Search!$P$10,N21)))),ROW(),"")) | N21: =IF(D21="",""," "&SUBSTITUTE(SUBSTITUTE(SUBSTITUTE(SUBSTITUTE(SUBSTITUTE(SUBSTITUTE(SUBSTITUTE(B21&" "&C21&" "&D21&" "&E21&" "&F21&" "&G21&" "&H21&" "&'01 Aluminium'!R23,"("," "),")"," "),"/"," "),"-"," "),","," "),";"," "),":"," ")&" ") -> AL 019 Standard Sections Aluminium heavy U channel frameless partition 40 x 40 mm 0.90 kg m Anodized PC Local lm 40x40 40mm aluminum alu stainless steel
A22: =IF('01 Aluminium'!$C$24="","","Aluminium Profiles & Systems") -> Aluminium Profiles & Systems | B22: =IF('01 Aluminium'!$C$24="","",'01 Aluminium'!A24) -> AL-020 | C22: =IF('01 Aluminium'!$C$24="","",'01 Aluminium'!B24) -> Sliding Window System | D22: =IF('01 Aluminium'!$C$24="","",'01 Aluminium'!C24) -> Sliding window outer frame - 2 track | E22: =IF('01 Aluminium'!$C$24="","",'01 Aluminium'!D24) -> Non-thermal (approx. 1.25 kg/m) | F22: =IF('01 Aluminium'!$C$24="","",'01 Aluminium'!E24) -> Powder coated | G22: =IF('01 Aluminium'!$C$24="","",'01 Aluminium'!F24) -> Gulf Extrusions / Equiv. | H22: =IF('01 Aluminium'!$C$24="","",'01 Aluminium'!G24) -> lm | I22: =IF('01 Aluminium'!$C$24="","",'01 Aluminium'!J24) -> 24.29 | J22: =IF('01 Aluminium'!$C$24="","",'01 Aluminium'!K24) -> 29.15 | K22: =IF('01 Aluminium'!$C$24="","",'01 Aluminium'!L24) -> 30.61 | L22: =IF('01 Aluminium'!$C$24="","",'01 Aluminium'!M24) -> Indicative | M22: =IF(D22="","",IF(AND(OR(Search!$C$6="All Categories",A22=Search!$C$6),OR(Search!$P$5="",ISNUMBER(SEARCH(" "&Search!$P$5,N22))),OR(Search!$P$6="",ISNUMBER(SEARCH(" "&Search!$P$6,N22))),OR(Search!$P$7="",ISNUMBER(SEARCH(" "&Search!$P$7,N22))),OR(Search!$P$8="",ISNUMBER(SEARCH(" "&Search!$P$8,N22))),OR(Search!$P$9="",ISNUMBER(SEARCH(" "&Search!$P$9,N22))),OR(Search!$P$10="",ISNUMBER(SEARCH(" "&Search!$P$10,N22)))),ROW(),"")) | N22: =IF(D22="",""," "&SUBSTITUTE(SUBSTITUTE(SUBSTITUTE(SUBSTITUTE(SUBSTITUTE(SUBSTITUTE(SUBSTITUTE(B22&" "&C22&" "&D22&" "&E22&" "&F22&" "&G22&" "&H22&" "&'01 Aluminium'!R24,"("," "),")"," "),"/"," "),"-"," "),","," "),";"," "),":"," ")&" ") -> AL 020 Sliding Window System Sliding window outer frame 2 track Non thermal approx. 1.25 kg m Powder coated Gulf Extrusions Equiv. lm pc
A23: =IF('01 Aluminium'!$C$25="","","Aluminium Profiles & Systems") -> Aluminium Profiles & Systems | B23: =IF('01 Aluminium'!$C$25="","",'01 Aluminium'!A25) -> AL-021 | C23: =IF('01 Aluminium'!$C$25="","",'01 Aluminium'!B25) -> Sliding Window System | D23: =IF('01 Aluminium'!$C$25="","",'01 Aluminium'!C25) -> Sliding window outer frame - 3 track | E23: =IF('01 Aluminium'!$C$25="","",'01 Aluminium'!D25) -> Non-thermal (approx. 1.75 kg/m) | F23: =IF('01 Aluminium'!$C$25="","",'01 Aluminium'!E25) -> Powder coated | G23: =IF('01 Aluminium'!$C$25="","",'01 Aluminium'!F25) -> Gulf Extrusions / Equiv. | H23: =IF('01 Aluminium'!$C$25="","",'01 Aluminium'!G25) -> lm | I23: =IF('01 Aluminium'!$C$25="","",'01 Aluminium'!J25) -> 34 | J23: =IF('01 Aluminium'!$C$25="","",'01 Aluminium'!K25) -> 40.8 | K23: =IF('01 Aluminium'!$C$25="","",'01 Aluminium'!L25) -> 42.84 | L23: =IF('01 Aluminium'!$C$25="","",'01 Aluminium'!M25) -> Indicative | M23: =IF(D23="","",IF(AND(OR(Search!$C$6="All Categories",A23=Search!$C$6),OR(Search!$P$5="",ISNUMBER(SEARCH(" "&Search!$P$5,N23))),OR(Search!$P$6="",ISNUMBER(SEARCH(" "&Search!$P$6,N23))),OR(Search!$P$7="",ISNUMBER(SEARCH(" "&Search!$P$7,N23))),OR(Search!$P$8="",ISNUMBER(SEARCH(" "&Search!$P$8,N23))),OR(Search!$P$9="",ISNUMBER(SEARCH(" "&Search!$P$9,N23))),OR(Search!$P$10="",ISNUMBER(SEARCH(" "&Search!$P$10,N23)))),ROW(),"")) | N23: =IF(D23="",""," "&SUBSTITUTE(SUBSTITUTE(SUBSTITUTE(SUBSTITUTE(SUBSTITUTE(SUBSTITUTE(SUBSTITUTE(B23&" "&C23&" "&D23&" "&E23&" "&F23&" "&G23&" "&H23&" "&'01 Aluminium'!R25,"("," "),")"," "),"/"," "),"-"," "),","," "),";"," "),":"," ")&" ") -> AL 021 Sliding Window System Sliding window outer frame 3 track Non thermal approx. 1.75 kg m Powder coated Gulf Extrusions Equiv. lm pc
A24: =IF('01 Aluminium'!$C$26="","","Aluminium Profiles & Systems") -> Aluminium Profiles & Systems | B24: =IF('01 Aluminium'!$C$26="","",'01 Aluminium'!A26) -> AL-022 | C24: =IF('01 Aluminium'!$C$26="","",'01 Aluminium'!B26) -> Sliding Window System | D24: =IF('01 Aluminium'!$C$26="","",'01 Aluminium'!C26) -> Sliding sash profile | E24: =IF('01 Aluminium'!$C$26="","",'01 Aluminium'!D26) -> Approx. 0.95 kg/m | F24: =IF('01 Aluminium'!$C$26="","",'01 Aluminium'!E26) -> Powder coated | G24: =IF('01 Aluminium'!$C$26="","",'01 Aluminium'!F26) -> Gulf Extrusions / Equiv. | H24: =IF('01 Aluminium'!$C$26="","",'01 Aluminium'!G26) -> lm | I24: =IF('01 Aluminium'!$C$26="","",'01 Aluminium'!J26) -> 18.46 | J24: =IF('01 Aluminium'!$C$26="","",'01 Aluminium'!K26) -> 22.15 | K24: =IF('01 Aluminium'!$C$26="","",'01 Aluminium'!L26) -> 23.26 | L24: =IF('01 Aluminium'!$C$26="","",'01 Aluminium'!M26) -> Indicative | M24: =IF(D24="","",IF(AND(OR(Search!$C$6="All Categories",A24=Search!$C$6),OR(Search!$P$5="",ISNUMBER(SEARCH(" "&Search!$P$5,N24))),OR(Search!$P$6="",ISNUMBER(SEARCH(" "&Search!$P$6,N24))),OR(Search!$P$7="",ISNUMBER(SEARCH(" "&Search!$P$7,N24))),OR(Search!$P$8="",ISNUMBER(SEARCH(" "&Search!$P$8,N24))),OR(Search!$P$9="",ISNUMBER(SEARCH(" "&Search!$P$9,N24))),OR(Search!$P$10="",ISNUMBER(SEARCH(" "&Search!$P$10,N24)))),ROW(),"")) | N24: =IF(D24="",""," "&SUBSTITUTE(SUBSTITUTE(SUBSTITUTE(SUBSTITUTE(SUBSTITUTE(SUBSTITUTE(SUBSTITUTE(B24&" "&C24&" "&D24&" "&E24&" "&F24&" "&G24&" "&H24&" "&'01 Aluminium'!R26,"("," "),")"," "),"/"," "),"-"," "),","," "),";"," "),":"," ")&" ") -> AL 022 Sliding Window System Sliding sash profile Approx. 0.95 kg m Powder coated Gulf Extrusions Equiv. lm pc
